<mujoco model="UF_ROBOT">
  <compiler angle="radian" meshdir="meshes_mujoco"/>

  <option integrator="implicitfast"/>

  <asset>
    <mesh name="collision_link_base" content_type="model/stl" file="collision_link_base.stl"/>
    <mesh name="collision_link1" content_type="model/stl" file="collision_link1.stl"/>
    <mesh name="collision_link2" content_type="model/stl" file="collision_link2.stl"/>
    <mesh name="collision_link3" content_type="model/stl" file="collision_link3.stl"/>
    <mesh name="collision_link4" content_type="model/stl" file="collision_link4.stl"/>
    <mesh name="collision_link5" content_type="model/stl" file="collision_link5.stl"/>
    <mesh name="collision_link6" content_type="model/stl" file="collision_link6.stl"/>
    <mesh name="collision_gripper_lite" content_type="model/stl" file="collision_gripper_lite.stl"/>
  </asset>

  <worldbody>
    <geom type="mesh" rgba="1 1 1 1" mesh="collision_link_base"/>
    <body name="link1" pos="0 0 0.2435">
      <inertial pos="-0.00036 0.04195 -0.0025" quat="0.608059 0.792349 -0.0438707 0.0228718" mass="1.411" diaginertia="0.00145276 0.00135275 0.000853355"/>
      <joint name="joint1" pos="0 0 0" axis="0 0 1" range="-6.28319 6.28319" actuatorfrcrange="-50 50" damping="1" armature="0.1"/>
      <geom type="mesh" rgba="1 1 1 1" mesh="collision_link1"/>
      <body name="link2" quat="-0.500004 0.499998 0.500002 0.499996">
        <inertial pos="0.179 0 0.0584" quat="0.417561 0.571619 0.569585 0.417693" mass="1.34" diaginertia="0.00560971 0.0052152 0.00122018"/>
        <joint name="joint2" pos="0 0 0" axis="0 0 1" range="-2.61799 2.61799" actuatorfrcrange="-50 50" damping="1" armature="0.1"/>
        <geom type="mesh" rgba="1 1 1 1" mesh="collision_link2"/>
        <body name="link3" pos="0.2002 0 0" quat="-2.59734e-06 -0.707105 -0.707108 -2.59735e-06">
          <inertial pos="0.072 -0.0357 -0.001" quat="0.128259 0.662963 -0.167256 0.71837" mass="0.953" diaginertia="0.0018521 0.00175546 0.000703807"/>
          <joint name="joint3" pos="0 0 0" axis="0 0 1" range="-0.061087 5.23599" actuatorfrcrange="-32 32" damping="1" armature="0.1"/>
          <geom type="mesh" rgba="1 1 1 1" mesh="collision_link3"/>
          <body name="link4" pos="0.087 -0.22761 0" quat="0.707105 0.707108 0 0">
            <inertial pos="-0.002 -0.0285 -0.0813" quat="0.975248 0.22109 0.00203498 -0.00262178" mass="1.284" diaginertia="0.00370503 0.00349091 0.00109586"/>
            <joint name="joint4" pos="0 0 0" axis="0 0 1" range="-6.28319 6.28319" actuatorfrcrange="-32 32" damping="1" armature="0.1"/>
            <geom type="mesh" rgba="1 1 1 1" mesh="collision_link4"/>
            <body name="link5" quat="0.707105 0.707108 0 0">
              <inertial pos="0 0.01 0.0019" quat="0.71423 0.696388 -0.0531933 0.0456997" mass="0.804" diaginertia="0.000567553 0.000529266 0.000507681"/>
              <joint name="joint5" pos="0 0 0" axis="0 0 1" range="-2.1642 2.1642" actuatorfrcrange="-32 32" damping="1" armature="0.1"/>
              <geom type="mesh" rgba="1 1 1 1" mesh="collision_link5"/>
              <body name="link6" pos="0 0.0625 0" quat="0.707105 -0.707108 0 0">
                <inertial pos="0 -0.000615122 0.0172537" quat="0.998482 -0.0548544 -0.00393177 -0.00304989" mass="0.41" diaginertia="0.000692149 0.00056176 0.00040297"/>
                <joint name="joint6" pos="0 0 0" axis="0 0 1" range="-6.28319 6.28319" actuatorfrcrange="-20 20" damping="1" armature="0.1"/>
                <geom type="mesh" rgba="0.753 0.753 0.753 1" mesh="collision_link6"/>
                <geom type="mesh" rgba="1 1 1 1" mesh="collision_gripper_lite"/>
              </body>
            </body>
          </body>
        </body>
      </body>
    </body>
  </worldbody>

  <actuator>
    <position name="joint1" joint="joint1" ctrlrange="-6.28319 6.28319" forcerange="-50 50"/>
    <position name="joint2" joint="joint2" ctrlrange="-2.61799 2.61799" forcerange="-50 50"/>
    <position name="joint3" joint="joint3" ctrlrange="-0.061087 5.23599" forcerange="-32 32"/>
    <position name="joint4" joint="joint4" ctrlrange="-6.28319 6.28319" forcerange="-32 32"/>
    <position name="joint5" joint="joint5" ctrlrange="-2.1642 2.1642"   forcerange="-32 32"/>
    <position name="joint6" joint="joint6" ctrlrange="-6.28319 6.28319" forcerange="-20 20"/>
  </actuator>
</mujoco>
